2022-12-14 21:31:32,719 ERROR: Exception on /search [GET] [in /Users/vlitvi/PycharmProjects/Flask/venv/lib/python3.8/site-packages/flask/app.py:1741]
Traceback (most recent call last):
  File "/Users/vlitvi/PycharmProjects/Flask/venv/lib/python3.8/site-packages/urllib3/connection.py", line 174, in _new_conn
    conn = connection.create_connection(
  File "/Users/vlitvi/PycharmProjects/Flask/venv/lib/python3.8/site-packages/urllib3/util/connection.py", line 95, in create_connection
    raise err
  File "/Users/vlitvi/PycharmProjects/Flask/venv/lib/python3.8/site-packages/urllib3/util/connection.py", line 85, in create_connection
    sock.connect(sa)
ConnectionRefusedError: [Errno 61] Connection refused

During handling of the above exception, another exception occurred:

Traceback (most recent call last):
  File "/Users/vlitvi/PycharmProjects/Flask/venv/lib/python3.8/site-packages/opensearchpy/connection/http_urllib3.py", line 240, in perform_request
    response = self.pool.urlopen(
  File "/Users/vlitvi/PycharmProjects/Flask/venv/lib/python3.8/site-packages/urllib3/connectionpool.py", line 787, in urlopen
    retries = retries.increment(
  File "/Users/vlitvi/PycharmProjects/Flask/venv/lib/python3.8/site-packages/urllib3/util/retry.py", line 525, in increment
    raise six.reraise(type(error), error, _stacktrace)
  File "/Users/vlitvi/PycharmProjects/Flask/venv/lib/python3.8/site-packages/urllib3/packages/six.py", line 770, in reraise
    raise value
  File "/Users/vlitvi/PycharmProjects/Flask/venv/lib/python3.8/site-packages/urllib3/connectionpool.py", line 703, in urlopen
    httplib_response = self._make_request(
  File "/Users/vlitvi/PycharmProjects/Flask/venv/lib/python3.8/site-packages/urllib3/connectionpool.py", line 398, in _make_request
    conn.request(method, url, **httplib_request_kw)
  File "/Users/vlitvi/PycharmProjects/Flask/venv/lib/python3.8/site-packages/urllib3/connection.py", line 239, in request
    super(HTTPConnection, self).request(method, url, body=body, headers=headers)
  File "/Library/Developer/CommandLineTools/Library/Frameworks/Python3.framework/Versions/3.8/lib/python3.8/http/client.py", line 1252, in request
    self._send_request(method, url, body, headers, encode_chunked)
  File "/Library/Developer/CommandLineTools/Library/Frameworks/Python3.framework/Versions/3.8/lib/python3.8/http/client.py", line 1298, in _send_request
    self.endheaders(body, encode_chunked=encode_chunked)
  File "/Library/Developer/CommandLineTools/Library/Frameworks/Python3.framework/Versions/3.8/lib/python3.8/http/client.py", line 1247, in endheaders
    self._send_output(message_body, encode_chunked=encode_chunked)
  File "/Library/Developer/CommandLineTools/Library/Frameworks/Python3.framework/Versions/3.8/lib/python3.8/http/client.py", line 1007, in _send_output
    self.send(msg)
  File "/Library/Developer/CommandLineTools/Library/Frameworks/Python3.framework/Versions/3.8/lib/python3.8/http/client.py", line 947, in send
    self.connect()
  File "/Users/vlitvi/PycharmProjects/Flask/venv/lib/python3.8/site-packages/urllib3/connection.py", line 205, in connect
    conn = self._new_conn()
  File "/Users/vlitvi/PycharmProjects/Flask/venv/lib/python3.8/site-packages/urllib3/connection.py", line 186, in _new_conn
    raise NewConnectionError(
urllib3.exceptions.NewConnectionError: <urllib3.connection.HTTPConnection object at 0x10c4355e0>: Failed to establish a new connection: [Errno 61] Connection refused

During handling of the above exception, another exception occurred:

Traceback (most recent call last):
  File "/Users/vlitvi/PycharmProjects/Flask/venv/lib/python3.8/site-packages/flask/app.py", line 2525, in wsgi_app
    response = self.full_dispatch_request()
  File "/Users/vlitvi/PycharmProjects/Flask/venv/lib/python3.8/site-packages/flask/app.py", line 1822, in full_dispatch_request
    rv = self.handle_user_exception(e)
  File "/Users/vlitvi/PycharmProjects/Flask/venv/lib/python3.8/site-packages/flask/app.py", line 1820, in full_dispatch_request
    rv = self.dispatch_request()
  File "/Users/vlitvi/PycharmProjects/Flask/venv/lib/python3.8/site-packages/flask/app.py", line 1796, in dispatch_request
    return self.ensure_sync(self.view_functions[rule.endpoint])(**view_args)
  File "/Users/vlitvi/PycharmProjects/Flask/venv/lib/python3.8/site-packages/flask_login/utils.py", line 290, in decorated_view
    return current_app.ensure_sync(func)(*args, **kwargs)
  File "/Users/vlitvi/PycharmProjects/Flask/app/main/routes.py", line 150, in search
    posts, total = Post.search(g.search_form.q.data, page,
  File "/Users/vlitvi/PycharmProjects/Flask/app/models.py", line 65, in search
    ids, total = query_index(cls.__tablename__, expression, page, per_page)
  File "/Users/vlitvi/PycharmProjects/Flask/app/search.py", line 19, in query_index
    search = current_app.opensearch.search(
  File "/Users/vlitvi/PycharmProjects/Flask/venv/lib/python3.8/site-packages/opensearchpy/client/utils.py", line 178, in _wrapped
    return func(*args, params=params, headers=headers, **kwargs)
  File "/Users/vlitvi/PycharmProjects/Flask/venv/lib/python3.8/site-packages/opensearchpy/client/__init__.py", line 1551, in search
    return self.transport.perform_request(
  File "/Users/vlitvi/PycharmProjects/Flask/venv/lib/python3.8/site-packages/opensearchpy/transport.py", line 406, in perform_request
    raise e
  File "/Users/vlitvi/PycharmProjects/Flask/venv/lib/python3.8/site-packages/opensearchpy/transport.py", line 369, in perform_request
    status, headers_response, data = connection.perform_request(
  File "/Users/vlitvi/PycharmProjects/Flask/venv/lib/python3.8/site-packages/opensearchpy/connection/http_urllib3.py", line 255, in perform_request
    raise ConnectionError("N/A", str(e), e)
opensearchpy.exceptions.ConnectionError: ConnectionError(<urllib3.connection.HTTPConnection object at 0x10c4355e0>: Failed to establish a new connection: [Errno 61] Connection refused) caused by: NewConnectionError(<urllib3.connection.HTTPConnection object at 0x10c4355e0>: Failed to establish a new connection: [Errno 61] Connection refused)
2022-12-21 21:34:51,062 INFO: Microblog startup [in /Users/vlitvi/PycharmProjects/Flask/app/__init__.py:66]
2022-12-21 21:34:58,903 INFO: Microblog startup [in /Users/vlitvi/PycharmProjects/Flask/app/__init__.py:66]
2022-12-26 19:50:39,947 INFO: Microblog startup [in /Users/vlitvi/PycharmProjects/Flask/app/__init__.py:66]
2022-12-26 19:50:53,839 INFO: Microblog startup [in /Users/vlitvi/PycharmProjects/Flask/app/__init__.py:66]
2022-12-27 22:04:25,257 INFO: Microblog startup [in /Users/makariy/PycharmProjects/Flask_project/app/__init__.py:66]
2022-12-27 22:08:31,007 INFO: Microblog startup [in /Users/makariy/PycharmProjects/Flask_project/app/__init__.py:66]
2022-12-27 22:09:36,386 INFO: Microblog startup [in /Users/makariy/PycharmProjects/Flask_project/app/__init__.py:66]
2022-12-27 22:09:36,386 INFO: Microblog startup [in /Users/makariy/PycharmProjects/Flask_project/app/__init__.py:66]
2022-12-27 22:16:53,772 INFO: Microblog startup [in /Users/makariy/PycharmProjects/Flask_project/app/__init__.py:66]
2022-12-27 22:16:53,772 INFO: Microblog startup [in /Users/makariy/PycharmProjects/Flask_project/app/__init__.py:66]
2022-12-27 22:16:53,772 INFO: Microblog startup [in /Users/makariy/PycharmProjects/Flask_project/app/__init__.py:66]
2022-12-27 22:20:04,656 INFO: Microblog startup [in /Users/makariy/PycharmProjects/Flask_project/app/__init__.py:66]
2022-12-27 22:20:51,061 INFO: Microblog startup [in /Users/makariy/PycharmProjects/Flask_project/app/__init__.py:66]
2022-12-27 22:20:51,061 INFO: Microblog startup [in /Users/makariy/PycharmProjects/Flask_project/app/__init__.py:66]
2022-12-27 22:22:29,268 INFO: Microblog startup [in /Users/makariy/PycharmProjects/Flask_project/app/__init__.py:66]
